<?xml version="1.0" ?>
<!-- =================================================================================== -->
<!-- |    This document was autogenerated by xacro from /home/belal/ros1_ws/robair-tp-sources/src/robair_description/urdf/robair.urdf.xacro | -->
<!-- |    EDITING THIS FILE BY HAND IS NOT RECOMMENDED                                 | -->
<!-- =================================================================================== -->
<robot name="robair">
  <material name="black">
    <color rgba="0.0 0.0 0.0 1.0"/>
  </material>
  <material name="blue">
    <color rgba="0.0 0.0 0.8 1.0"/>
  </material>
  <material name="green">
    <color rgba="0.0 0.8 0.0 1.0"/>
  </material>
  <material name="gray">
    <color rgba="0.7 0.7 0.7 1.0"/>
  </material>
  <material name="darkgray">
    <color rgba="0.3 0.3 0.3 1.0"/>
  </material>
  <material name="red">
    <color rgba="0.8 0.0 0.0 1.0"/>
  </material>
  <material name="white">
    <color rgba="1.0 1.0 1.0 1.0"/>
  </material>
  <material name="yellow">
    <color rgba="0.8 0.8 0.0 1.0"/>
  </material>
  <!-- ######################### Links ############################### -->
  <link name="robair_body">
    <inertial>
      <mass value="10"/>
      <inertia ixx="0.4" ixy="0.0" ixz="0.0" iyy="0.4" iyz="0.0" izz="0.2"/>
    </inertial>
    <visual>
      <origin rpy="0 0 0" xyz="0 0 0.1"/>
      <geometry>
        <box size="0.5 0.3 0.2"/>
      </geometry>
      <material name="Cyan">
        <color rgba="0 1.0 1.0 0.7"/>
      </material>
    </visual>
    <collision>
      <origin rpy="0 0 0" xyz="0 0 0.1"/>
      <geometry>
        <box size="0.5 0.3 0.2"/>
      </geometry>
    </collision>
  </link>
  <link name="right_wheel_link">
    <inertial>
      <mass value="2.637"/>
      <origin xyz="0 0 0"/>
      <inertia ixx="0.02467" ixy="0" ixz="0" iyy="0.04411" iyz="0" izz="0.02467"/>
    </inertial>
    <visual>
      <origin rpy="0 0 0" xyz="0 0 0"/>
      <geometry>
        <mesh filename="package://robair_description/meshes/wheel.dae" scale="0.5 0.5 0.5"/>
      </geometry>
    </visual>
    <!-- TODO: collision description to be fixed! -->
    <collision>
      <origin rpy="-1.570795 0 0" xyz="0 0 0"/>
      <geometry>
        <cylinder length="0.05" radius="0.08"/>
      </geometry>
    </collision>
  </link>
  <gazebo reference="right_wheel_link">
    <mu1 value="1.0"/>
    <mu2 value="1.0"/>
    <kp value="10000000.0"/>
    <kd value="1.0"/>
    <fdir1 value="1 0 0"/>
  </gazebo>
  <joint name="right_wheel" type="continuous">
    <parent link="robair_body"/>
    <child link="right_wheel_link"/>
    <origin rpy="0 0 0" xyz="0 0.174 0.01"/>
    <axis rpy="0 0 0" xyz="0 1 0"/>
  </joint>
  <transmission name="right_wheel_trans" type="SimpleTransmission">
    <type>transmission_interface/SimpleTransmission</type>
    <actuator name="right_wheel_motor">
      <mechanicalReduction>1</mechanicalReduction>
    </actuator>
    <joint name="right_wheel">
      <hardwareInterface>hardware_interface/VelocityJointInterface</hardwareInterface>
    </joint>
  </transmission>
  <link name="left_wheel_link">
    <inertial>
      <mass value="2.637"/>
      <origin xyz="0 0 0"/>
      <inertia ixx="0.02467" ixy="0" ixz="0" iyy="0.04411" iyz="0" izz="0.02467"/>
    </inertial>
    <visual>
      <origin rpy="0 0 0" xyz="0 0 0"/>
      <geometry>
        <mesh filename="package://robair_description/meshes/wheel.dae" scale="0.5 0.5 0.5"/>
      </geometry>
    </visual>
    <!-- TODO: collision description to be fixed! -->
    <collision>
      <origin rpy="-1.570795 0 0" xyz="0 0 0"/>
      <geometry>
        <cylinder length="0.05" radius="0.08"/>
      </geometry>
    </collision>
  </link>
  <gazebo reference="left_wheel_link">
    <mu1 value="1.0"/>
    <mu2 value="1.0"/>
    <kp value="10000000.0"/>
    <kd value="1.0"/>
    <fdir1 value="1 0 0"/>
  </gazebo>
  <joint name="left_wheel" type="continuous">
    <parent link="robair_body"/>
    <child link="left_wheel_link"/>
    <origin rpy="0 0 0" xyz="0 -0.174 0.01"/>
    <axis rpy="0 0 0" xyz="0 1 0"/>
  </joint>
  <transmission name="left_wheel_trans" type="SimpleTransmission">
    <type>transmission_interface/SimpleTransmission</type>
    <actuator name="left_wheel_motor">
      <mechanicalReduction>1</mechanicalReduction>
    </actuator>
    <joint name="left_wheel">
      <hardwareInterface>hardware_interface/VelocityJointInterface</hardwareInterface>
    </joint>
  </transmission>
  <link name="front_caster_wheel_link">
    <inertial>
      <mass value="2.637"/>
      <origin xyz="0 0 0"/>
      <inertia ixx="0.02467" ixy="0" ixz="0" iyy="0.04411" iyz="0" izz="0.02467"/>
    </inertial>
    <visual>
      <origin rpy="0 0 0" xyz="0 0 0"/>
      <geometry>
        <mesh filename="package://robair_description/meshes/caster_wheel.dae" scale="2 2 2"/>
      </geometry>
      <material name="white">
        <color rgba="1.0 1.0 1.0 0.5"/>
      </material>
    </visual>
    <collision>
      <origin rpy="0 0 0" xyz="-0.02 0 -0.05"/>
      <geometry>
        <box size="0.07 0.07 0.07"/>
      </geometry>
    </collision>
  </link>
  <joint name="front_caster_wheel" type="fixed">
    <parent link="robair_body"/>
    <child link="front_caster_wheel_link"/>
    <origin rpy="0 0 0" xyz="0.15 0 0.01"/>
  </joint>
  <link name="rear_caster_wheel_link">
    <inertial>
      <mass value="2.637"/>
      <origin xyz="0 0 0"/>
      <inertia ixx="0.02467" ixy="0" ixz="0" iyy="0.04411" iyz="0" izz="0.02467"/>
    </inertial>
    <visual>
      <origin rpy="0 0 0" xyz="0 0 0"/>
      <geometry>
        <mesh filename="package://robair_description/meshes/caster_wheel.dae" scale="2 2 2"/>
      </geometry>
      <material name="white">
        <color rgba="1.0 1.0 1.0 0.5"/>
      </material>
    </visual>
    <collision>
      <origin rpy="0 0 0" xyz="-0.02 0 -0.05"/>
      <geometry>
        <box size="0.07 0.07 0.07"/>
      </geometry>
    </collision>
  </link>
  <joint name="rear_caster_wheel" type="fixed">
    <parent link="robair_body"/>
    <child link="rear_caster_wheel_link"/>
    <origin rpy="0 0 0" xyz="-0.15 0 0.01"/>
  </joint>
  <!-- ########## Joints ################### -->
  <!-- base_link -->
  <link name="world"/>
  <joint name="parent_to_robair_body_joint" type="fixed">
    <parent link="world"/>
    <child link="robair_body"/>
    <origin rpy="0 0 0" xyz="-0.25 0 -0.22"/>
  </joint>
  <link name="_laser">
    <inertial>
      <mass value="1.1"/>
      <origin xyz="0 0 0"/>
      <inertia ixx="0.00307156543804" ixy="0.0" ixz="0.0" iyy="0.0031284904152700005" iyz="0.0" izz="0.00196432421427"/>
    </inertial>
  </link>
  <gazebo reference="_laser">
    <turnGravityOff>true</turnGravityOff>
    <sensor name="_laser" type="ray">
      <pose>0 0 0 0 0 0</pose>
      <visualize>false</visualize>
      <update_rate>50</update_rate>
      <ray>
        <scan>
          <horizontal>
            <samples>720</samples>
            <resolution>1</resolution>
            <min_angle>-2.35619</min_angle>
            <max_angle>2.35619</max_angle>
          </horizontal>
        </scan>
        <range>
          <min>0.1</min>
          <max>30.0</max>
          <resolution>0.01</resolution>
        </range>
        <noise>
          <type>gaussian</type>
          <mean>0.0</mean>
          <stddev>0.001</stddev>
        </noise>
      </ray>
      <plugin filename="libgazebo_ros_laser.so" name="gazebo_ros_laser">
        <topicName>/scan</topicName>
        <frameName>_laser</frameName>
        <robotNamespace>/</robotNamespace>
      </plugin>
    </sensor>
  </gazebo>
  <joint name="_laser_mount_joint" type="fixed">
    <origin rpy="0 0 0" xyz="0.2206 0.0 0.0"/>
    <parent link="robair_body"/>
    <child link="_laser_mount"/>
  </joint>
  <link name="_laser_mount">
    <visual>
      <origin rpy="0 0 0" xyz="0.0 0 0.2"/>
      <geometry>
        <!-- Origin of this mesh is the base of the bracket. -->
        <mesh filename="package://urg_node/meshes/hokuyo_ust10.stl"/>
      </geometry>
      <material name="black"/>
    </visual>
    <collision>
      <origin rpy="0 0 0" xyz="0.0 0 0.24"/>
      <geometry>
        <!-- Origin of this mesh is the base of the bracket. -->
        <cylinder length="0.08" radius="0.03"/>
      </geometry>
      <material name="black"/>
    </collision>
  </link>
  <joint name="_laser_joint" type="fixed">
    <!-- This offset is from the base of the bracket to the LIDAR's focal point. -->
    <origin rpy="0 0 0" xyz="0.0 0 0.0474"/>
    <parent link="_laser_mount"/>
    <child link="_laser"/>
  </joint>
  <gazebo reference="_laser_mount">
    <material>Gazebo/Black</material>
  </gazebo>
  <!-- Interface with Gazebo ros control -->
  <gazebo>
    <plugin filename="libgazebo_ros_control.so" name="gazebo_ros_control">
      <robotNamespace>/robair</robotNamespace>
    </plugin>
  </gazebo>
</robot>
